Return-Path: <linux-doc-owner@vger.kernel.org>
X-Original-To: lists+linux-doc@lfdr.de
Delivered-To: lists+linux-doc@lfdr.de
Received: from vger.kernel.org (vger.kernel.org [23.128.96.18])
	by mail.lfdr.de (Postfix) with ESMTP id 3A51E37B66E
	for <lists+linux-doc@lfdr.de>; Wed, 12 May 2021 09:02:01 +0200 (CEST)
Received: (majordomo@vger.kernel.org) by vger.kernel.org via listexpand
        id S229803AbhELHDH (ORCPT <rfc822;lists+linux-doc@lfdr.de>);
        Wed, 12 May 2021 03:03:07 -0400
Received: from mx2.suse.de ([195.135.220.15]:48902 "EHLO mx2.suse.de"
        rhost-flags-OK-OK-OK-OK) by vger.kernel.org with ESMTP
        id S229626AbhELHDH (ORCPT <rfc822;linux-doc@vger.kernel.org>);
        Wed, 12 May 2021 03:03:07 -0400
X-Virus-Scanned: by amavisd-new at test-mx.suse.de
Received: from relay2.suse.de (unknown [195.135.221.27])
        by mx2.suse.de (Postfix) with ESMTP id 28AFEAFDC;
        Wed, 12 May 2021 07:01:59 +0000 (UTC)
Date:   Wed, 12 May 2021 09:01:57 +0200
From:   Michal =?iso-8859-1?Q?Such=E1nek?= <msuchanek@suse.de>
To:     Mauro Carvalho Chehab <mchehab@kernel.org>
Cc:     Markus Heiser <markus.heiser@darmarit.de>,
        linux-doc@vger.kernel.org, Jonathan Corbet <corbet@lwn.net>
Subject: Re: Sphinx parallel build error: UnicodeEncodeError: 'latin-1' codec
 can't encode characters in position 18-20: ordinal not in range(256)
Message-ID: <20210512070157.GQ12700@kitsune.suse.cz>
References: <20210506103913.GE6564@kitsune.suse.cz>
 <30f2117f-aa38-6d60-f020-ff5cf8f004b5@darmarit.de>
 <20210506184641.6348a621@coco.lan>
 <0fd5bb54-a8fc-84b2-2bd6-31ab12f12303@darmarit.de>
 <20210506174849.GH6564@kitsune.suse.cz>
 <20210512082238.682f6aea@coco.lan>
MIME-Version: 1.0
Content-Type: text/plain; charset=utf-8
Content-Disposition: inline
Content-Transfer-Encoding: 8bit
In-Reply-To: <20210512082238.682f6aea@coco.lan>
User-Agent: Mutt/1.10.1 (2018-07-13)
Precedence: bulk
List-ID: <linux-doc.vger.kernel.org>
X-Mailing-List: linux-doc@vger.kernel.org

On Wed, May 12, 2021 at 08:22:38AM +0200, Mauro Carvalho Chehab wrote:
> Hi Michal,
> 
> Em Thu, 6 May 2021 19:48:49 +0200
> Michal Suchánek <msuchanek@suse.de> escreveu:
> 
> > [  127s] + :
> > [  127s] + locale
> > [  128s] LANG=en_US
> > [  128s] LC_CTYPE="en_US"
> > [  128s] LC_NUMERIC="en_US"
> > [  128s] LC_TIME="en_US"
> > [  128s] LC_COLLATE="en_US"
> > [  128s] LC_MONETARY="en_US"
> > [  128s] LC_MESSAGES="en_US"
> > [  128s] LC_PAPER="en_US"
> > [  128s] LC_NAME="en_US"
> > [  128s] LC_ADDRESS="en_US"
> > [  128s] LC_TELEPHONE="en_US"
> > [  128s] LC_MEASUREMENT="en_US"
> > [  128s] LC_IDENTIFICATION="en_US"
> > [  128s] LC_ALL=
> > [  128s] + echo LC_ALL=
> > [  128s] LC_ALL=
> > [  128s] + echo LANG=en_US
> > [  128s] LANG=en_US
> 
> Where those the locale settings that you used when the build
> failed?
> 
> I tried to reproduce the bug here with, disabling the parallel run (as
> it masks the real error) with both:
> 
> 	$ for i in LANG LC_ALL LC_ADDRESS LC_IDENTIFICATION LC_MEASUREMENT LC_MONETARY LC_NAME LC_NUMERIC LC_PAPER LC_TELEPHONE LC_TIME; do echo $i=en_US; done
> 	$ make cleandocs && make SPHINXOPTS=-j1 htmldocs
> 
> (this one caused lots of warnings on Debian, due to the
>  settings at /etc/locale.gen)
> 
> and:
> 
> 	$ for i in LANG LC_ALL LC_ADDRESS LC_IDENTIFICATION LC_MEASUREMENT LC_MONETARY LC_NAME LC_NUMERIC LC_PAPER LC_TELEPHONE LC_TIME; do echo $i=en_US.ISO-8859-1; done
> 	$ make cleandocs && make SPHINXOPTS=-j1 htmldocs
> 
> Without any success.
> 
> Could you please provide more details about the build VM and the git 
> changeset that caused the issue?

It depends on what character set your en_US locale implements.

~> cat test.py 
print("↑ᛏ个")
~> locale
LANG=en_US.utf8
LC_CTYPE="en_US.utf8"
LC_NUMERIC="en_US.utf8"
LC_TIME="en_US.utf8"
LC_COLLATE="en_US.utf8"
LC_MONETARY="en_US.utf8"
LC_MESSAGES="en_US.utf8"
LC_PAPER="en_US.utf8"
LC_NAME="en_US.utf8"
LC_ADDRESS="en_US.utf8"
LC_TELEPHONE="en_US.utf8"
LC_MEASUREMENT="en_US.utf8"
LC_IDENTIFICATION="en_US.utf8"
LC_ALL=
~> python3 test.py 
↑ᛏ个
~> LANG=en_US python3 test.py 
Traceback (most recent call last):
  File "test.py", line 1, in <module>
    print("\u2191\u16cf\u4e2a\uf8f9")
UnicodeEncodeError: 'latin-1' codec can't encode characters in position 0-3: ordinal not in range(256)
~> LANG=C python3 test.py 
↑ᛏ个

You can easily test if your python version can print UTF-8 in a specific
locale, and if necessary define an ISO-8859-1 locale for testing.
On some systems the situation is reversed - C locale is ASCII only, and
en_US is UTF-8, and it is possible that some systems don't ship an 8bit
locale at all.

Thanks

Michal
